Workbook
Name Ders_Listesi: 'Veri Bankası'!$I$2:$I$10
Name TYT_Türkçe: 'Veri Bankası'!$C$2:$C$72
Name TYT_Turkce: 'Veri Bankası'!$C$2:$C$72
Name TYT_AYT_Tarih: 'Veri Bankası'!$C$73:$C$238
Name TYT_Coğrafya: 'Veri Bankası'!$C$239:$C$298
Name TYT_Cografya: 'Veri Bankası'!$C$239:$C$298
Name AYT_Coğrafya: 'Veri Bankası'!$C$299:$C$352
Name AYT_Cografya: 'Veri Bankası'!$C$299:$C$352
Name TYT_Matematik: 'Veri Bankası'!$C$353:$C$470
Name TYT_Biyoloji: 'Veri Bankası'!$C$471:$C$550
Name TYT_Fizik: 'Veri Bankası'!$C$551:$C$626
Name TYT_Kimya: 'Veri Bankası'!$C$627:$C$705
Name AYT_Edebiyat: 'Veri Bankası'!$C$706:$C$767
Name Veri_Tablosu: 'Veri Bankası'!$A$2:$G$767

Sheet Hazır YKS Kamp Takvimi
A1: 🎯 YKS 2027 ÇALIŞMA PLANI • 42 HAFTALIK BÜYÜK KAMP
A2: 📌 Günde 4 Blok Video (1 Blok = 1 Video) • Bloklar Arası 20 Dk Mola • Pazar Günleri Dinlenme • Hedef: 19 Haziran 2027
A4: 📊 KAMP DURUMU | B4: TOPLAM VİDEO | C4: İZLENEN VİDEO | D4: KALAN VİDEO | E4: İLERLEME | F4: TOPLAM SAAT | G4: BİTEN SAAT
B5: 766 | C5: =COUNTIF(G8:G3500, "X") -> 0 | D5: =B5-C5 -> 766 | E5: =IFERROR(C5/B5, 0) -> 0 | F5: =ROUND(SUM('Veri Bankası'!D2:D767)/60, 1) -> 443.8 | G5: =IFERROR(ROUND((C5/B5)*F5, 1), 0) -> 0
A7: Hafta / Gün / Blok | B7: Ders | C7: Video / Konu Başlığı | D7: Eğitmen & Kanal | E7: Süre (Dk) | F7: YouTube Linki | G7: Tamamlandı [X]
A8: 📅 1. HAFTA PROGRAMI
A9: 📌 Pazartesi (4 Blok Video + 3 Mola)
A10: 1. Blok | B10: TYT Türkçe | C10: 2027 ~ Türkçe Derse Giriş / Aker KARTAL | D10: Aker Kartal | E10: 11.7 | F10: İzle
A11: Mola 1 | B11: ☕ 20 Dk Mola | C11: Zihni Dinlendir & Beyin Resetleme | D11: - | F11: - | G11: -
A12: 2. Blok | B12: TYT Türkçe | C12: 1) Ses Bilgisi - 1 | Aker KARTAL - 2027 | D12: Aker Kartal | E12: 37.3 | F12: İzle
A13: Mola 2 | B13: ☕ 20 Dk Mola | C13: Zihni Dinlendir & Beyin Resetleme | D13: - | F13: - | G13: -
A14: 3. Blok | B14: TYT Coğrafya | C14: TYT COĞRAFYA KAMPI 2027 I Coğrafya çalışma programı | D14: Yunus Hoca (Coğrafyanın Kodları) | E14: 27 | F14: İzle
A15: Mola 3 | B15: ☕ 20 Dk Mola | C15: Zihni Dinlendir & Beyin Resetleme | D15: - | F15: - | G15: -
A16: 4. Blok | B16: TYT Coğrafya | C16: 39 Günde tyt coğrafya kampı 2026 - 2027 | ZEDUVA 1 KİTAP 3 KAMP | D16: Yunus Hoca (Coğrafyanın Kodları) | E16: 14.4 | F16: İzle
A17: Günlük Toplam | B17: 4 Blok + 3 Mola | C17: Günlük Çalışma & Mola | D17: Toplam Mola: 60 Dk | E17: =SUM(E10,E12,E14,E16) -> 90.4 | F17: =ROUND(E17/60, 1) & " Saat" -> 1.5 Saat | G17: =COUNTIF(G10:G16, "X") & "/4" -> 0/4
A18: 📌 Salı (4 Blok Video + 3 Mola)
A19: 1. Blok | B19: TYT Matematik | C19: 2027 TYT Matematik Kamplarımız | D19: Selim Yüksel (Bıyıklı Matematik) | E19: 23.3 | F19: İzle
A20: Mola 1 | B20: ☕ 20 Dk Mola | C20: Zihni Dinlendir & Beyin Resetleme | D20: - | F20: - | G20: -
A21: 2. Blok | B21: TYT Matematik | C21: 55 Günde TYT Matematik Kampı | 1. Gün | Temel İşlem Aritmetiği | Konu Anlatımı 2027 | D21: Selim Yüksel (Bıyıklı Matematik) | E21: 46.7 | F21: İzle
A22: Mola 2 | B22: ☕ 20 Dk Mola | C22: Zihni Dinlendir & Beyin Resetleme | D22: - | F22: - | G22: -
A23: 3. Blok | B23: TYT-AYT Tarih | C23: 1) Geçmişin İnşa Sürecinde Tarih | YKS-Tarih | Mehmet Celal ÖZYILDIZ - 2027 | D23: Mehmet Celal Özyıldız | E23: 30.4 | F23: İzle
A24: Mola 3 | B24: ☕ 20 Dk Mola | C24: Zihni Dinlendir & Beyin Resetleme | D24: - | F24: - | G24: -
A25: 4. Blok | B25: TYT-AYT Tarih | C25: 2)Geçmişin İnşa Sürecinde Tarih | Tarihin Sınıflandırılması |YKS-Tarih| Mehmet Celal ÖZYILDIZ - 2027 | D25: Mehmet Celal Özyıldız | E25: 30.2 | F25: İzle
A26: Günlük Toplam | B26: 4 Blok + 3 Mola | C26: Günlük Çalışma & Mola | D26: Toplam Mola: 60 Dk | E26: =SUM(E19,E21,E23,E25) -> 130.6 | F26: =ROUND(E26/60, 1) & " Saat" -> 2.2 Saat | G26: =COUNTIF(G19:G25, "X") & "/4" -> 0/4
A27: 📌 Çarşamba (4 Blok Video + 3 Mola)
A28: 1. Blok | B28: TYT Biyoloji | C28: TYT Biyoloji - 39 Günde Biyolojiyi Fullemek İçin - 2027 Yol Haritası | D28: Semih Hoca (Biosem) | E28: 9.3 | F28: İzle
A29: Mola 1 | B29: ☕ 20 Dk Mola | C29: Zihni Dinlendir & Beyin Resetleme | D29: - | F29: - | G29: -
A30: 2. Blok | B30: TYT Biyoloji | C30: 39 Günde tyt biyoloji kampı 2027 - 2028 | ZEDUVA 1 KİTAP 3 KAMP | D30: Semih Hoca (Biosem) | E30: 13.4 | F30: İzle
A31: Mola 2 | B31: ☕ 20 Dk Mola | C31: Zihni Dinlendir & Beyin Resetleme | D31: - | F31: - | G31: -
A32: 3. Blok | B32: AYT Edebiyat | C32: RÖNTGENİNİ ÇEKTİM: AYT EDEBİYAT SORU DAĞILIMI / Konuları / Çalışma Önerileri / ÖSYM'nin Sordukları | D32: Deniz Hoca | E32: 25.6 | F32: İzle
A33: Mola 3 | B33: ☕ 20 Dk Mola | C33: Zihni Dinlendir & Beyin Resetleme | D33: - | F33: - | G33: -
A34: 4. Blok | B34: AYT Edebiyat | C34: SANAT VE EDEBİYAT | 1.Gün | 📌 2026 AYT Edebiyat Kampı | D34: Deniz Hoca | E34: 17.6 | F34: İzle
A35: Günlük Toplam | B35: 4 Blok + 3 Mola | C35: Günlük Çalışma & Mola | D35: Toplam Mola: 60 Dk | E35: =SUM(E28,E30,E32,E34) -> 65.9 | F35: =ROUND(E35/60, 1) & " Saat" -> 1.1 Saat | G35: =COUNTIF(G28:G34, "X") & "/4" -> 0/4
A36: 📌 Perşembe (4 Blok Video + 3 Mola)
A37: 1. Blok | B37: TYT Matematik | C37: 55 Günde TYT Matematik Kampı | 1. Gün | Temel İşlem Aritmetiği | ÖSYM Yaklaşım Soruları 2027 | D37: Selim Yüksel (Bıyıklı Matematik) | E37: 31.6 | F37: İzle
A38: Mola 1 | B38: ☕ 20 Dk Mola | C38: Zihni Dinlendir & Beyin Resetleme | D38: - | F38: - | G38: -
A39: 2. Blok | B39: TYT Matematik | C39: 55 Günde TYT Matematik Kampı | 2. Gün | Temel Kavramlar | Konu Anlatımı 2027 | D39: Selim Yüksel (Bıyıklı Matematik) | E39: 80.3 | F39: İzle
A40: Mola 2 | B40: ☕ 20 Dk Mola | C40: Zihni Dinlendir & Beyin Resetleme | D40: - | F40: - | G40: -
A41: 3. Blok | B41: TYT Kimya | C41: 39 günde tyt kimya 2026-2027 | ZEDUVA 1 KİTAP 3 KAMP | D41: Mesut Hoca (Meschemy Kimya) | E41: 17.6 | F41: İzle
A42: Mola 3 | B42: ☕ 20 Dk Mola | C42: Zihni Dinlendir & Beyin Resetleme | D42: - | F42: - | G42: -
...

Sheet Dinamik Haftalık Planlayıcı
A1: 🎯 DİNAMİK HAFTALIK ÇALIŞMA PLANLAYICI (ÖZELLEŞTİRİLEBİLİR)
A2: 💡 Kullanım: Ders seçin -> Video konusunu seçin -> Süre ve YouTube linki otomatik gelir. Günde 4 blok ve 20 dk mola esastır.
A4: Gün / Blok | B4: Ders Seçimi | C4: Video / Konu Adı | D4: Süre (Dk) | E4: Mola (Dk) | F4: YouTube Linki | G4: Tamamlandı [X]
A5: 📌 PAZARTESI (4 Blok + 3 Mola)
A6: 1. Blok | D6: =IFERROR(VLOOKUP(C6, 'Veri Bankası'!$C:$D, 2, FALSE), "") | F6: =IFERROR(HYPERLINK(VLOOKUP(C6, 'Veri Bankası'!$C:$G, 5, FALSE), "İzle"), "")
A7: Mola 1 | B7: ☕ Mola | C7: 20 Dakika Zihinsel Dinlenme | E7: 20 | F7: - | G7: -
A8: 2. Blok | D8: =IFERROR(VLOOKUP(C8, 'Veri Bankası'!$C:$D, 2, FALSE), "") | F8: =IFERROR(HYPERLINK(VLOOKUP(C8, 'Veri Bankası'!$C:$G, 5, FALSE), "İzle"), "")
A9: Mola 2 | B9: ☕ Mola | C9: 20 Dakika Zihinsel Dinlenme | E9: 20 | F9: - | G9: -
A10: 3. Blok | D10: =IFERROR(VLOOKUP(C10, 'Veri Bankası'!$C:$D, 2, FALSE), "") | F10: =IFERROR(HYPERLINK(VLOOKUP(C10, 'Veri Bankası'!$C:$G, 5, FALSE), "İzle"), "")
A11: Mola 3 | B11: ☕ Mola | C11: 20 Dakika Zihinsel Dinlenme | E11: 20 | F11: - | G11: -
A12: 4. Blok | D12: =IFERROR(VLOOKUP(C12, 'Veri Bankası'!$C:$D, 2, FALSE), "") | F12: =IFERROR(HYPERLINK(VLOOKUP(C12, 'Veri Bankası'!$C:$G, 5, FALSE), "İzle"), "")
A13: Günlük Toplam | B13: 4 Blok + 3 Mola | C13: Toplam Çalışma & Mola | D13: =IFERROR(SUM(D6,D8,D10,D12), 0) -> 0 | E13: =SUM(E7,E9,E11) -> 60 | F13: =IF(D13>0, "~" & ROUND(D13/60, 1) & " Saat", "-") -> - | G13: =COUNTIF(G6:G12, "X") & "/4" -> 0/4
A14: 📌 SALI (4 Blok + 3 Mola)
A15: 1. Blok | D15: =IFERROR(VLOOKUP(C15, 'Veri Bankası'!$C:$D, 2, FALSE), "") | F15: =IFERROR(HYPERLINK(VLOOKUP(C15, 'Veri Bankası'!$C:$G, 5, FALSE), "İzle"), "")
A16: Mola 1 | B16: ☕ Mola | C16: 20 Dakika Zihinsel Dinlenme | E16: 20 | F16: - | G16: -
A17: 2. Blok | D17: =IFERROR(VLOOKUP(C17, 'Veri Bankası'!$C:$D, 2, FALSE), "") | F17: =IFERROR(HYPERLINK(VLOOKUP(C17, 'Veri Bankası'!$C:$G, 5, FALSE), "İzle"), "")
A18: Mola 2 | B18: ☕ Mola | C18: 20 Dakika Zihinsel Dinlenme | E18: 20 | F18: - | G18: -
A19: 3. Blok | D19: =IFERROR(VLOOKUP(C19, 'Veri Bankası'!$C:$D, 2, FALSE), "") | F19: =IFERROR(HYPERLINK(VLOOKUP(C19, 'Veri Bankası'!$C:$G, 5, FALSE), "İzle"), "")
A20: Mola 3 | B20: ☕ Mola | C20: 20 Dakika Zihinsel Dinlenme | E20: 20 | F20: - | G20: -
A21: 4. Blok | D21: =IFERROR(VLOOKUP(C21, 'Veri Bankası'!$C:$D, 2, FALSE), "") | F21: =IFERROR(HYPERLINK(VLOOKUP(C21, 'Veri Bankası'!$C:$G, 5, FALSE), "İzle"), "")
A22: Günlük Toplam | B22: 4 Blok + 3 Mola | C22: Toplam Çalışma & Mola | D22: =IFERROR(SUM(D15,D17,D19,D21), 0) -> 0 | E22: =SUM(E16,E18,E20) -> 60 | F22: =IF(D22>0, "~" & ROUND(D22/60, 1) & " Saat", "-") -> - | G22: =COUNTIF(G15:G21, "X") & "/4" -> 0/4
A23: 📌 ÇARŞAMBA (4 Blok + 3 Mola)
A24: 1. Blok | D24: =IFERROR(VLOOKUP(C24, 'Veri Bankası'!$C:$D, 2, FALSE), "") | F24: =IFERROR(HYPERLINK(VLOOKUP(C24, 'Veri Bankası'!$C:$G, 5, FALSE), "İzle"), "")
A25: Mola 1 | B25: ☕ Mola | C25: 20 Dakika Zihinsel Dinlenme | E25: 20 | F25: - | G25: -
A26: 2. Blok | D26: =IFERROR(VLOOKUP(C26, 'Veri Bankası'!$C:$D, 2, FALSE), "") | F26: =IFERROR(HYPERLINK(VLOOKUP(C26, 'Veri Bankası'!$C:$G, 5, FALSE), "İzle"), "")
A27: Mola 2 | B27: ☕ Mola | C27: 20 Dakika Zihinsel Dinlenme | E27: 20 | F27: - | G27: -
A28: 3. Blok | D28: =IFERROR(VLOOKUP(C28, 'Veri Bankası'!$C:$D, 2, FALSE), "") | F28: =IFERROR(HYPERLINK(VLOOKUP(C28, 'Veri Bankası'!$C:$G, 5, FALSE), "İzle"), "")
A29: Mola 3 | B29: ☕ Mola | C29: 20 Dakika Zihinsel Dinlenme | E29: 20 | F29: - | G29: -
A30: 4. Blok | D30: =IFERROR(VLOOKUP(C30, 'Veri Bankası'!$C:$D, 2, FALSE), "") | F30: =IFERROR(HYPERLINK(VLOOKUP(C30, 'Veri Bankası'!$C:$G, 5, FALSE), "İzle"), "")
A31: Günlük Toplam | B31: 4 Blok + 3 Mola | C31: Toplam Çalışma & Mola | D31: =IFERROR(SUM(D24,D26,D28,D30), 0) -> 0 | E31: =SUM(E25,E27,E29) -> 60 | F31: =IF(D31>0, "~" & ROUND(D31/60, 1) & " Saat", "-") -> - | G31: =COUNTIF(G24:G30, "X") & "/4" -> 0/4
A32: 📌 PERŞEMBE (4 Blok + 3 Mola)
A33: 1. Blok | D33: =IFERROR(VLOOKUP(C33, 'Veri Bankası'!$C:$D, 2, FALSE), "") | F33: =IFERROR(HYPERLINK(VLOOKUP(C33, 'Veri Bankası'!$C:$G, 5, FALSE), "İzle"), "")
A34: Mola 1 | B34: ☕ Mola | C34: 20 Dakika Zihinsel Dinlenme | E34: 20 | F34: - | G34: -
A35: 2. Blok | D35: =IFERROR(VLOOKUP(C35, 'Veri Bankası'!$C:$D, 2, FALSE), "") | F35: =IFERROR(HYPERLINK(VLOOKUP(C35, 'Veri Bankası'!$C:$G, 5, FALSE), "İzle"), "")
A36: Mola 2 | B36: ☕ Mola | C36: 20 Dakika Zihinsel Dinlenme | E36: 20 | F36: - | G36: -
A37: 3. Blok | D37: =IFERROR(VLOOKUP(C37, 'Veri Bankası'!$C:$D, 2, FALSE), "") | F37: =IFERROR(HYPERLINK(VLOOKUP(C37, 'Veri Bankası'!$C:$G, 5, FALSE), "İzle"), "")
A38: Mola 3 | B38: ☕ Mola | C38: 20 Dakika Zihinsel Dinlenme | E38: 20 | F38: - | G38: -
A39: 4. Blok | D39: =IFERROR(VLOOKUP(C39, 'Veri Bankası'!$C:$D, 2, FALSE), "") | F39: =IFERROR(HYPERLINK(VLOOKUP(C39, 'Veri Bankası'!$C:$G, 5, FALSE), "İzle"), "")
A40: Günlük Toplam | B40: 4 Blok + 3 Mola | C40: Toplam Çalışma & Mola | D40: =IFERROR(SUM(D33,D35,D37,D39), 0) -> 0 | E40: =SUM(E34,E36,E38) -> 60 | F40: =IF(D40>0, "~" & ROUND(D40/60, 1) & " Saat", "-") -> - | G40: =COUNTIF(G33:G39, "X") & "/4" -> 0/4
A41: 📌 CUMA (4 Blok + 3 Mola)
...

Sheet Veri Bankası
A1: Ders | B1: Sıra No | C1: Video Başlığı | D1: Süre (Dk) | E1: Süre (Saniye) | F1: Eğitmen & Kanal | G1: YouTube URL | I1: Ders Listesi
A2: TYT Türkçe | B2: 1 | C2: 2027 ~ Türkçe Derse Giriş / Aker KARTAL | D2: 11.7 | E2: 704 | F2: Aker Kartal (Retro Yayıncılık) | G2: https://www.youtube.com/watch?v=JiIDhhHGRJo | I2: TYT Türkçe
A3: TYT Türkçe | B3: 2 | C3: 1) Ses Bilgisi - 1 | Aker KARTAL - 2027 | D3: 37.3 | E3: 2239 | F3: Aker Kartal (Retro Yayıncılık) | G3: https://www.youtube.com/watch?v=juJFHVk7ieE | I3: TYT-AYT Tarih
A4: TYT Türkçe | B4: 3 | C4: 2) Ses Bilgisi - 2 | Aker KARTAL - 2027 | D4: 31.9 | E4: 1912 | F4: Aker Kartal (Retro Yayıncılık) | G4: https://www.youtube.com/watch?v=_jpMxZQ3PF0 | I4: TYT Coğrafya
A5: TYT Türkçe | B5: 4 | C5: 3) Ses Bilgisi - 3 | Aker KARTAL - 2027 | D5: 34.5 | E5: 2068 | F5: Aker Kartal (Retro Yayıncılık) | G5: https://www.youtube.com/watch?v=L0LrvZN0iqY | I5: AYT Coğrafya
A6: TYT Türkçe | B6: 5 | C6: 4) Ses Bilgisi - 4 | Aker KARTAL - 2027 | D6: 18.8 | E6: 1125 | F6: Aker Kartal (Retro Yayıncılık) | G6: https://www.youtube.com/watch?v=Ym4ZBYlY6Q8 | I6: TYT Matematik
A7: TYT Türkçe | B7: 6 | C7: 5) Ses Bilgisi | ÖSYM Analizi | Aker KARTAL - 2027 | D7: 9.6 | E7: 578 | F7: Aker Kartal (Retro Yayıncılık) | G7: https://www.youtube.com/watch?v=pDJsRjdzzlc | I7: TYT Biyoloji
A8: TYT Türkçe | B8: 7 | C8: 6) Ses Bilgisi | Soru Çözüm | Aker KARTAL - 2027 | D8: 14.7 | E8: 879 | F8: Aker Kartal (Retro Yayıncılık) | G8: https://www.youtube.com/watch?v=HNLnHGWoa5U | I8: TYT Fizik
A9: TYT Türkçe | B9: 8 | C9: 7) Ses Bilgisi | Sözün Özü | Aker KARTAL - 2027 | D9: 7.2 | E9: 433 | F9: Aker Kartal (Retro Yayıncılık) | G9: https://www.youtube.com/watch?v=1EHh06Rm6j0 | I9: TYT Kimya
A10: TYT Türkçe | B10: 9 | C10: 8) Yazım Kuralları - 1 | Aker KARTAL - 2027 | D10: 36.2 | E10: 2175 | F10: Aker Kartal (Retro Yayıncılık) | G10: https://www.youtube.com/watch?v=X--d21iqVcc | I10: AYT Edebiyat
A11: TYT Türkçe | B11: 10 | C11: 9) Yazım Kuralları - 2 | Aker KARTAL - 2027 | D11: 26.6 | E11: 1595 | F11: Aker Kartal (Retro Yayıncılık) | G11: https://www.youtube.com/watch?v=SrjCETJKxPc
A12: TYT Türkçe | B12: 11 | C12: 10) Yazım Kuralları - 3 | Aker KARTAL - 2027 | D12: 24.9 | E12: 1493 | F12: Aker Kartal (Retro Yayıncılık) | G12: https://www.youtube.com/watch?v=U3rtA9J_9Po
A13: TYT Türkçe | B13: 12 | C13: 11) Yazım Kuralları - 4 | Aker KARTAL - 2027 | D13: 25.9 | E13: 1551 | F13: Aker Kartal (Retro Yayıncılık) | G13: https://www.youtube.com/watch?v=vXa24tRYd54
A14: TYT Türkçe | B14: 13 | C14: 12) Yazım Kuralları - 5 | Aker KARTAL - 2027 | D14: 16.7 | E14: 1002 | F14: Aker Kartal (Retro Yayıncılık) | G14: https://www.youtube.com/watch?v=VG7kNIjOym0
A15: TYT Türkçe | B15: 14 | C15: 13) Yazım Kuralları | ÖSYM Analizi | Aker KARTAL - 2027 | D15: 15.4 | E15: 924 | F15: Aker Kartal (Retro Yayıncılık) | G15: https://www.youtube.com/watch?v=yrDGepjFQjs
A16: TYT Türkçe | B16: 15 | C16: 14) Yazım Kuralları | Soru Çözümü | Aker KARTAL - 2027 | D16: 12.3 | E16: 737 | F16: Aker Kartal (Retro Yayıncılık) | G16: https://www.youtube.com/watch?v=A4TnHAFVMwg
A17: TYT Türkçe | B17: 16 | C17: 15) Yazım Kuralları | Sözün Özü | Aker KARTAL - 2027 | D17: 6.5 | E17: 390 | F17: Aker Kartal (Retro Yayıncılık) | G17: https://www.youtube.com/watch?v=_yoaoMfjrX8
A18: TYT Türkçe | B18: 17 | C18: 16) Noktalama İşaretleri - 1 | Aker KARTAL - 2027 | D18: 22.6 | E18: 1358 | F18: Aker Kartal (Retro Yayıncılık) | G18: https://www.youtube.com/watch?v=CpCxBmpQdjM
A19: TYT Türkçe | B19: 18 | C19: 17) Noktalama İşaretleri - 2 | Aker KARTAL - 2027 | D19: 20.8 | E19: 1247 | F19: Aker Kartal (Retro Yayıncılık) | G19: https://www.youtube.com/watch?v=gZMekG0GA4g
A20: TYT Türkçe | B20: 19 | C20: 18) Noktalama İşaretleri - 3 | Aker KARTAL - 2027 | D20: 10.6 | E20: 633 | F20: Aker Kartal (Retro Yayıncılık) | G20: https://www.youtube.com/watch?v=W7T6nsbB9cQ
A21: TYT Türkçe | B21: 20 | C21: 19) Noktalama İşaretleri | ÖSYM Analizi | Aker KARTAL - 2027 | D21: 16.8 | E21: 1008 | F21: Aker Kartal (Retro Yayıncılık) | G21: https://www.youtube.com/watch?v=gBHRbffGkas
A22: TYT Türkçe | B22: 21 | C22: 20) Noktalama İşaretleri | Soru Çözümü | Aker KARTAL - 2027 | D22: 17.3 | E22: 1040 | F22: Aker Kartal (Retro Yayıncılık) | G22: https://www.youtube.com/watch?v=brj0TtkJ75E
... A767: AYT Edebiyat | B767: 62 | C767: CUMHURİYET DÖNEMİ ÖĞRETİCİ METİNLER | 59.Gün | 📌 2026 AYT Edebiyat Kampı | D767: 27.8 | E767: 1670 | F767: Deniz Hoca (Deniz Hoca) | G767: https://www.youtube.com/watch?v=HsEUVpW7QUo
